[12/Sep/2016 19:50:18] ERROR [django.request:256] Internal Server Error: /estatebase/clientcreate/
Traceback (most recent call last):
  File "/usr/local/lib/python2.7/dist-packages/django/core/handlers/base.py", line 132, in get_response
    response = wrapped_callback(request, *callback_args, **callback_kwargs)
  File "/usr/local/lib/python2.7/dist-packages/django/views/generic/base.py", line 71, in view
    return self.dispatch(request, *args, **kwargs)
  File "/usr/local/lib/python2.7/dist-packages/django/views/generic/base.py", line 89, in dispatch
    return handler(request, *args, **kwargs)
  File "/usr/local/lib/python2.7/dist-packages/django/views/generic/edit.py", line 249, in post
    return super(BaseCreateView, self).post(request, *args, **kwargs)
  File "/usr/local/lib/python2.7/dist-packages/django/views/generic/edit.py", line 215, in post
    return self.form_valid(form)
  File "/home/picasso/Documents/DjangoSpace/estate-agent/realestate/estatebase/views.py", line 631, in form_valid
    if contact_form.is_valid():
  File "/usr/local/lib/python2.7/dist-packages/django/forms/formsets.py", line 304, in is_valid
    self.errors
  File "/usr/local/lib/python2.7/dist-packages/django/forms/formsets.py", line 278, in errors
    self.full_clean()
  File "/usr/local/lib/python2.7/dist-packages/django/forms/formsets.py", line 327, in full_clean
    self._errors.append(form.errors)
  File "/usr/local/lib/python2.7/dist-packages/django/forms/forms.py", line 176, in errors
    self.full_clean()
  File "/usr/local/lib/python2.7/dist-packages/django/forms/forms.py", line 394, in full_clean
    self._post_clean()
  File "/usr/local/lib/python2.7/dist-packages/django/forms/models.py", line 426, in _post_clean
    self.instance.full_clean(exclude=exclude, validate_unique=False)
  File "/usr/local/lib/python2.7/dist-packages/django/db/models/base.py", line 1156, in full_clean
    self.clean()
  File "/home/picasso/Documents/DjangoSpace/estate-agent/realestate/estatebase/models.py", line 1192, in clean
    if self.contact_type.id == self.PHONE:
  File "/usr/local/lib/python2.7/dist-packages/django/db/models/fields/related.py", line 620, in __get__
    "%s has no %s." % (self.field.model.__name__, self.field.name)
RelatedObjectDoesNotExist: Contact has no contact_type.
[12/Sep/2016 19:51:14] ERROR [django.request:256] Internal Server Error: /estatebase/clientcreate/
Traceback (most recent call last):
  File "/usr/local/lib/python2.7/dist-packages/django/core/handlers/base.py", line 132, in get_response
    response = wrapped_callback(request, *callback_args, **callback_kwargs)
  File "/usr/local/lib/python2.7/dist-packages/django/views/generic/base.py", line 71, in view
    return self.dispatch(request, *args, **kwargs)
  File "/usr/local/lib/python2.7/dist-packages/django/views/generic/base.py", line 89, in dispatch
    return handler(request, *args, **kwargs)
  File "/usr/local/lib/python2.7/dist-packages/django/views/generic/edit.py", line 249, in post
    return super(BaseCreateView, self).post(request, *args, **kwargs)
  File "/usr/local/lib/python2.7/dist-packages/django/views/generic/edit.py", line 215, in post
    return self.form_valid(form)
  File "/home/picasso/Documents/DjangoSpace/estate-agent/realestate/estatebase/views.py", line 631, in form_valid
    if contact_form.is_valid():
  File "/usr/local/lib/python2.7/dist-packages/django/forms/formsets.py", line 304, in is_valid
    self.errors
  File "/usr/local/lib/python2.7/dist-packages/django/forms/formsets.py", line 278, in errors
    self.full_clean()
  File "/usr/local/lib/python2.7/dist-packages/django/forms/formsets.py", line 327, in full_clean
    self._errors.append(form.errors)
  File "/usr/local/lib/python2.7/dist-packages/django/forms/forms.py", line 176, in errors
    self.full_clean()
  File "/usr/local/lib/python2.7/dist-packages/django/forms/forms.py", line 394, in full_clean
    self._post_clean()
  File "/usr/local/lib/python2.7/dist-packages/django/forms/models.py", line 426, in _post_clean
    self.instance.full_clean(exclude=exclude, validate_unique=False)
  File "/usr/local/lib/python2.7/dist-packages/django/db/models/base.py", line 1156, in full_clean
    self.clean()
  File "/home/picasso/Documents/DjangoSpace/estate-agent/realestate/estatebase/models.py", line 1204, in clean
    t = t.render(Context({ 'name': client.name, 'pk': client.pk }))
  File "/usr/local/lib/python2.7/dist-packages/django/template/base.py", line 210, in render
    return self._render(context)
  File "/usr/local/lib/python2.7/dist-packages/django/test/utils.py", line 96, in instrumented_test_render
    return self.nodelist.render(context)
  File "/usr/local/lib/python2.7/dist-packages/django/template/base.py", line 905, in render
    bit = self.render_node(node, context)
  File "/usr/local/lib/python2.7/dist-packages/django/template/debug.py", line 79, in render_node
    return node.render(context)
  File "/usr/local/lib/python2.7/dist-packages/django/template/defaulttags.py", line 507, in render
    six.reraise(*exc_info)
  File "/usr/local/lib/python2.7/dist-packages/django/template/defaulttags.py", line 493, in render
    url = reverse(view_name, args=args, kwargs=kwargs, current_app=current_app)
  File "/usr/local/lib/python2.7/dist-packages/django/core/urlresolvers.py", line 578, in reverse
    return force_text(iri_to_uri(resolver._reverse_with_prefix(view, prefix, *args, **kwargs)))
  File "/usr/local/lib/python2.7/dist-packages/django/core/urlresolvers.py", line 495, in _reverse_with_prefix
    (lookup_view_s, args, kwargs, len(patterns), patterns))
NoReverseMatch: Reverse for '' with arguments '(139085,)' and keyword arguments '{}' not found. 0 pattern(s) tried: []
[12/Sep/2016 19:53:37] ERROR [django.request:256] Internal Server Error: /estatebase/clientcreate/
Traceback (most recent call last):
  File "/usr/local/lib/python2.7/dist-packages/django/core/handlers/base.py", line 132, in get_response
    response = wrapped_callback(request, *callback_args, **callback_kwargs)
  File "/usr/local/lib/python2.7/dist-packages/django/views/generic/base.py", line 71, in view
    return self.dispatch(request, *args, **kwargs)
  File "/usr/local/lib/python2.7/dist-packages/django/views/generic/base.py", line 89, in dispatch
    return handler(request, *args, **kwargs)
  File "/usr/local/lib/python2.7/dist-packages/django/views/generic/edit.py", line 249, in post
    return super(BaseCreateView, self).post(request, *args, **kwargs)
  File "/usr/local/lib/python2.7/dist-packages/django/views/generic/edit.py", line 215, in post
    return self.form_valid(form)
  File "/home/picasso/Documents/DjangoSpace/estate-agent/realestate/estatebase/views.py", line 631, in form_valid
    if contact_form.is_valid():
  File "/usr/local/lib/python2.7/dist-packages/django/forms/formsets.py", line 304, in is_valid
    self.errors
  File "/usr/local/lib/python2.7/dist-packages/django/forms/formsets.py", line 278, in errors
    self.full_clean()
  File "/usr/local/lib/python2.7/dist-packages/django/forms/formsets.py", line 327, in full_clean
    self._errors.append(form.errors)
  File "/usr/local/lib/python2.7/dist-packages/django/forms/forms.py", line 176, in errors
    self.full_clean()
  File "/usr/local/lib/python2.7/dist-packages/django/forms/forms.py", line 394, in full_clean
    self._post_clean()
  File "/usr/local/lib/python2.7/dist-packages/django/forms/models.py", line 426, in _post_clean
    self.instance.full_clean(exclude=exclude, validate_unique=False)
  File "/usr/local/lib/python2.7/dist-packages/django/db/models/base.py", line 1156, in full_clean
    self.clean()
  File "/home/picasso/Documents/DjangoSpace/estate-agent/realestate/estatebase/models.py", line 1192, in clean
    if self.contact_type.id == self.PHONE:
  File "/usr/local/lib/python2.7/dist-packages/django/db/models/fields/related.py", line 620, in __get__
    "%s has no %s." % (self.field.model.__name__, self.field.name)
RelatedObjectDoesNotExist: Contact has no contact_type.
[12/Sep/2016 19:54:49] ERROR [django.request:256] Internal Server Error: /estatebase/clientcreate/
Traceback (most recent call last):
  File "/usr/local/lib/python2.7/dist-packages/django/core/handlers/base.py", line 132, in get_response
    response = wrapped_callback(request, *callback_args, **callback_kwargs)
  File "/usr/local/lib/python2.7/dist-packages/django/views/generic/base.py", line 71, in view
    return self.dispatch(request, *args, **kwargs)
  File "/usr/local/lib/python2.7/dist-packages/django/views/generic/base.py", line 89, in dispatch
    return handler(request, *args, **kwargs)
  File "/usr/local/lib/python2.7/dist-packages/django/views/generic/edit.py", line 249, in post
    return super(BaseCreateView, self).post(request, *args, **kwargs)
  File "/usr/local/lib/python2.7/dist-packages/django/views/generic/edit.py", line 215, in post
    return self.form_valid(form)
  File "/home/picasso/Documents/DjangoSpace/estate-agent/realestate/estatebase/views.py", line 631, in form_valid
    if contact_form.is_valid():
  File "/usr/local/lib/python2.7/dist-packages/django/forms/formsets.py", line 304, in is_valid
    self.errors
  File "/usr/local/lib/python2.7/dist-packages/django/forms/formsets.py", line 278, in errors
    self.full_clean()
  File "/usr/local/lib/python2.7/dist-packages/django/forms/formsets.py", line 327, in full_clean
    self._errors.append(form.errors)
  File "/usr/local/lib/python2.7/dist-packages/django/forms/forms.py", line 176, in errors
    self.full_clean()
  File "/usr/local/lib/python2.7/dist-packages/django/forms/forms.py", line 394, in full_clean
    self._post_clean()
  File "/usr/local/lib/python2.7/dist-packages/django/forms/models.py", line 426, in _post_clean
    self.instance.full_clean(exclude=exclude, validate_unique=False)
  File "/usr/local/lib/python2.7/dist-packages/django/db/models/base.py", line 1156, in full_clean
    self.clean()
  File "/home/picasso/Documents/DjangoSpace/estate-agent/realestate/estatebase/models.py", line 1192, in clean
    if not self.contact_type:
  File "/usr/local/lib/python2.7/dist-packages/django/db/models/fields/related.py", line 620, in __get__
    "%s has no %s." % (self.field.model.__name__, self.field.name)
RelatedObjectDoesNotExist: Contact has no contact_type.
[12/Sep/2016 19:55:10] ERROR [django.request:256] Internal Server Error: /estatebase/clientcreate/
Traceback (most recent call last):
  File "/usr/local/lib/python2.7/dist-packages/django/core/handlers/base.py", line 132, in get_response
    response = wrapped_callback(request, *callback_args, **callback_kwargs)
  File "/usr/local/lib/python2.7/dist-packages/django/views/generic/base.py", line 71, in view
    return self.dispatch(request, *args, **kwargs)
  File "/usr/local/lib/python2.7/dist-packages/django/views/generic/base.py", line 89, in dispatch
    return handler(request, *args, **kwargs)
  File "/usr/local/lib/python2.7/dist-packages/django/views/generic/edit.py", line 249, in post
    return super(BaseCreateView, self).post(request, *args, **kwargs)
  File "/usr/local/lib/python2.7/dist-packages/django/views/generic/edit.py", line 215, in post
    return self.form_valid(form)
  File "/home/picasso/Documents/DjangoSpace/estate-agent/realestate/estatebase/views.py", line 631, in form_valid
    if contact_form.is_valid():
  File "/usr/local/lib/python2.7/dist-packages/django/forms/formsets.py", line 304, in is_valid
    self.errors
  File "/usr/local/lib/python2.7/dist-packages/django/forms/formsets.py", line 278, in errors
    self.full_clean()
  File "/usr/local/lib/python2.7/dist-packages/django/forms/formsets.py", line 327, in full_clean
    self._errors.append(form.errors)
  File "/usr/local/lib/python2.7/dist-packages/django/forms/forms.py", line 176, in errors
    self.full_clean()
  File "/usr/local/lib/python2.7/dist-packages/django/forms/forms.py", line 394, in full_clean
    self._post_clean()
  File "/usr/local/lib/python2.7/dist-packages/django/forms/models.py", line 426, in _post_clean
    self.instance.full_clean(exclude=exclude, validate_unique=False)
  File "/usr/local/lib/python2.7/dist-packages/django/db/models/base.py", line 1156, in full_clean
    self.clean()
  File "/home/picasso/Documents/DjangoSpace/estate-agent/realestate/estatebase/models.py", line 1192, in clean
    if not self.contact_type:
  File "/usr/local/lib/python2.7/dist-packages/django/db/models/fields/related.py", line 620, in __get__
    "%s has no %s." % (self.field.model.__name__, self.field.name)
RelatedObjectDoesNotExist: Contact has no contact_type.
[12/Sep/2016 19:59:33] ERROR [django.request:256] Internal Server Error: /estatebase/clientcreate/
Traceback (most recent call last):
  File "/usr/local/lib/python2.7/dist-packages/django/core/handlers/base.py", line 132, in get_response
    response = wrapped_callback(request, *callback_args, **callback_kwargs)
  File "/usr/local/lib/python2.7/dist-packages/django/views/generic/base.py", line 71, in view
    return self.dispatch(request, *args, **kwargs)
  File "/usr/local/lib/python2.7/dist-packages/django/views/generic/base.py", line 89, in dispatch
    return handler(request, *args, **kwargs)
  File "/usr/local/lib/python2.7/dist-packages/django/views/generic/edit.py", line 249, in post
    return super(BaseCreateView, self).post(request, *args, **kwargs)
  File "/usr/local/lib/python2.7/dist-packages/django/views/generic/edit.py", line 215, in post
    return self.form_valid(form)
  File "/home/picasso/Documents/DjangoSpace/estate-agent/realestate/estatebase/views.py", line 631, in form_valid
    if contact_form.is_valid():
  File "/usr/local/lib/python2.7/dist-packages/django/forms/formsets.py", line 304, in is_valid
    self.errors
  File "/usr/local/lib/python2.7/dist-packages/django/forms/formsets.py", line 278, in errors
    self.full_clean()
  File "/usr/local/lib/python2.7/dist-packages/django/forms/formsets.py", line 327, in full_clean
    self._errors.append(form.errors)
  File "/usr/local/lib/python2.7/dist-packages/django/forms/forms.py", line 176, in errors
    self.full_clean()
  File "/usr/local/lib/python2.7/dist-packages/django/forms/forms.py", line 394, in full_clean
    self._post_clean()
  File "/usr/local/lib/python2.7/dist-packages/django/forms/models.py", line 426, in _post_clean
    self.instance.full_clean(exclude=exclude, validate_unique=False)
  File "/usr/local/lib/python2.7/dist-packages/django/db/models/base.py", line 1156, in full_clean
    self.clean()
  File "/home/picasso/Documents/DjangoSpace/estate-agent/realestate/estatebase/models.py", line 1192, in clean
    if not self.contact_type:
  File "/usr/local/lib/python2.7/dist-packages/django/db/models/fields/related.py", line 620, in __get__
    "%s has no %s." % (self.field.model.__name__, self.field.name)
RelatedObjectDoesNotExist: Contact has no contact_type.
[12/Sep/2016 20:01:29] ERROR [django.request:256] Internal Server Error: /estatebase/clientcreate/
Traceback (most recent call last):
  File "/usr/local/lib/python2.7/dist-packages/django/core/handlers/base.py", line 132, in get_response
    response = wrapped_callback(request, *callback_args, **callback_kwargs)
  File "/usr/local/lib/python2.7/dist-packages/django/views/generic/base.py", line 71, in view
    return self.dispatch(request, *args, **kwargs)
  File "/usr/local/lib/python2.7/dist-packages/django/views/generic/base.py", line 89, in dispatch
    return handler(request, *args, **kwargs)
  File "/usr/local/lib/python2.7/dist-packages/django/views/generic/edit.py", line 249, in post
    return super(BaseCreateView, self).post(request, *args, **kwargs)
  File "/usr/local/lib/python2.7/dist-packages/django/views/generic/edit.py", line 215, in post
    return self.form_valid(form)
  File "/home/picasso/Documents/DjangoSpace/estate-agent/realestate/estatebase/views.py", line 631, in form_valid
    if contact_form.is_valid():
  File "/usr/local/lib/python2.7/dist-packages/django/forms/formsets.py", line 304, in is_valid
    self.errors
  File "/usr/local/lib/python2.7/dist-packages/django/forms/formsets.py", line 278, in errors
    self.full_clean()
  File "/usr/local/lib/python2.7/dist-packages/django/forms/formsets.py", line 327, in full_clean
    self._errors.append(form.errors)
  File "/usr/local/lib/python2.7/dist-packages/django/forms/forms.py", line 176, in errors
    self.full_clean()
  File "/usr/local/lib/python2.7/dist-packages/django/forms/forms.py", line 394, in full_clean
    self._post_clean()
  File "/usr/local/lib/python2.7/dist-packages/django/forms/models.py", line 426, in _post_clean
    self.instance.full_clean(exclude=exclude, validate_unique=False)
  File "/usr/local/lib/python2.7/dist-packages/django/db/models/base.py", line 1156, in full_clean
    self.clean()
  File "/home/picasso/Documents/DjangoSpace/estate-agent/realestate/estatebase/models.py", line 1192, in clean
    if not self.contact_type:
  File "/usr/local/lib/python2.7/dist-packages/django/db/models/fields/related.py", line 620, in __get__
    "%s has no %s." % (self.field.model.__name__, self.field.name)
RelatedObjectDoesNotExist: Contact has no contact_type.
[12/Sep/2016 20:04:06] ERROR [django.request:256] Internal Server Error: /estatebase/clientcreate/
Traceback (most recent call last):
  File "/usr/local/lib/python2.7/dist-packages/django/core/handlers/base.py", line 132, in get_response
    response = wrapped_callback(request, *callback_args, **callback_kwargs)
  File "/usr/local/lib/python2.7/dist-packages/django/views/generic/base.py", line 71, in view
    return self.dispatch(request, *args, **kwargs)
  File "/usr/local/lib/python2.7/dist-packages/django/views/generic/base.py", line 89, in dispatch
    return handler(request, *args, **kwargs)
  File "/usr/local/lib/python2.7/dist-packages/django/views/generic/edit.py", line 249, in post
    return super(BaseCreateView, self).post(request, *args, **kwargs)
  File "/usr/local/lib/python2.7/dist-packages/django/views/generic/edit.py", line 215, in post
    return self.form_valid(form)
  File "/home/picasso/Documents/DjangoSpace/estate-agent/realestate/estatebase/views.py", line 631, in form_valid
    if contact_form.is_valid():
  File "/usr/local/lib/python2.7/dist-packages/django/forms/formsets.py", line 304, in is_valid
    self.errors
  File "/usr/local/lib/python2.7/dist-packages/django/forms/formsets.py", line 278, in errors
    self.full_clean()
  File "/usr/local/lib/python2.7/dist-packages/django/forms/formsets.py", line 327, in full_clean
    self._errors.append(form.errors)
  File "/usr/local/lib/python2.7/dist-packages/django/forms/forms.py", line 176, in errors
    self.full_clean()
  File "/usr/local/lib/python2.7/dist-packages/django/forms/forms.py", line 394, in full_clean
    self._post_clean()
  File "/usr/local/lib/python2.7/dist-packages/django/forms/models.py", line 426, in _post_clean
    self.instance.full_clean(exclude=exclude, validate_unique=False)
  File "/usr/local/lib/python2.7/dist-packages/django/db/models/base.py", line 1156, in full_clean
    self.clean()
  File "/home/picasso/Documents/DjangoSpace/estate-agent/realestate/estatebase/models.py", line 1198, in clean
    if self.contact_type.id == self.PHONE:
  File "/usr/local/lib/python2.7/dist-packages/django/db/models/fields/related.py", line 620, in __get__
    "%s has no %s." % (self.field.model.__name__, self.field.name)
RelatedObjectDoesNotExist: Contact has no contact_type.
[12/Sep/2016 20:06:04] ERROR [django.request:256] Internal Server Error: /estatebase/clientcreate/
Traceback (most recent call last):
  File "/usr/local/lib/python2.7/dist-packages/django/core/handlers/base.py", line 132, in get_response
    response = wrapped_callback(request, *callback_args, **callback_kwargs)
  File "/usr/local/lib/python2.7/dist-packages/django/views/generic/base.py", line 71, in view
    return self.dispatch(request, *args, **kwargs)
  File "/usr/local/lib/python2.7/dist-packages/django/views/generic/base.py", line 89, in dispatch
    return handler(request, *args, **kwargs)
  File "/usr/local/lib/python2.7/dist-packages/django/views/generic/edit.py", line 249, in post
    return super(BaseCreateView, self).post(request, *args, **kwargs)
  File "/usr/local/lib/python2.7/dist-packages/django/views/generic/edit.py", line 215, in post
    return self.form_valid(form)
  File "/home/picasso/Documents/DjangoSpace/estate-agent/realestate/estatebase/views.py", line 631, in form_valid
    if contact_form.is_valid():
  File "/usr/local/lib/python2.7/dist-packages/django/forms/formsets.py", line 304, in is_valid
    self.errors
  File "/usr/local/lib/python2.7/dist-packages/django/forms/formsets.py", line 278, in errors
    self.full_clean()
  File "/usr/local/lib/python2.7/dist-packages/django/forms/formsets.py", line 327, in full_clean
    self._errors.append(form.errors)
  File "/usr/local/lib/python2.7/dist-packages/django/forms/forms.py", line 176, in errors
    self.full_clean()
  File "/usr/local/lib/python2.7/dist-packages/django/forms/forms.py", line 394, in full_clean
    self._post_clean()
  File "/usr/local/lib/python2.7/dist-packages/django/forms/models.py", line 426, in _post_clean
    self.instance.full_clean(exclude=exclude, validate_unique=False)
  File "/usr/local/lib/python2.7/dist-packages/django/db/models/base.py", line 1156, in full_clean
    self.clean()
  File "/home/picasso/Documents/DjangoSpace/estate-agent/realestate/estatebase/models.py", line 1197, in clean
    if contact_type and contact_type.id == self.PHONE:
UnboundLocalError: local variable 'contact_type' referenced before assignment
[12/Sep/2016 20:28:55] ERROR [django.request:256] Internal Server Error: /estatebase/estatelist/
Traceback (most recent call last):
  File "/usr/local/lib/python2.7/dist-packages/django/core/handlers/base.py", line 164, in get_response
    response = response.render()
  File "/usr/local/lib/python2.7/dist-packages/django/template/response.py", line 158, in render
    self.content = self.rendered_content
  File "/usr/local/lib/python2.7/dist-packages/django/template/response.py", line 133, in rendered_content
    template = self._resolve_template(self.template_name)
  File "/usr/local/lib/python2.7/dist-packages/django/template/response.py", line 88, in _resolve_template
    new_template = self.resolve_template(template)
  File "/usr/local/lib/python2.7/dist-packages/django/template/response.py", line 78, in resolve_template
    return loader.select_template(template, using=self.using)
  File "/usr/local/lib/python2.7/dist-packages/django/template/loader.py", line 64, in select_template
    return engine.get_template(template_name, dirs)
  File "/usr/local/lib/python2.7/dist-packages/django/template/backends/django.py", line 30, in get_template
    return Template(self.engine.get_template(template_name, dirs))
  File "/usr/local/lib/python2.7/dist-packages/django/template/engine.py", line 167, in get_template
    template, origin = self.find_template(template_name, dirs)
  File "/usr/local/lib/python2.7/dist-packages/django/template/engine.py", line 141, in find_template
    source, display_name = loader(name, dirs)
  File "/usr/local/lib/python2.7/dist-packages/django/template/loaders/base.py", line 13, in __call__
    return self.load_template(template_name, template_dirs)
  File "/usr/local/lib/python2.7/dist-packages/django/template/loaders/cached.py", line 62, in load_template
    template, origin = self.find_template(template_name, template_dirs)
  File "/usr/local/lib/python2.7/dist-packages/django/template/loaders/cached.py", line 41, in find_template
    template, display_name = loader(name, dirs)
  File "/usr/local/lib/python2.7/dist-packages/django/template/loaders/base.py", line 13, in __call__
    return self.load_template(template_name, template_dirs)
  File "/usr/local/lib/python2.7/dist-packages/django/template/loaders/base.py", line 23, in load_template
    template = Template(source, origin, template_name, self.engine)
  File "/usr/local/lib/python2.7/dist-packages/django/template/base.py", line 191, in __init__
    self.nodelist = engine.compile_string(template_string, origin)
  File "/usr/local/lib/python2.7/dist-packages/django/template/engine.py", line 261, in compile_string
    return parser.parse()
  File "/usr/local/lib/python2.7/dist-packages/django/template/base.py", line 342, in parse
    compiled_result = compile_func(self, token)
  File "/usr/local/lib/python2.7/dist-packages/django/template/loader_tags.py", line 210, in do_extends
    nodelist = parser.parse()
  File "/usr/local/lib/python2.7/dist-packages/django/template/base.py", line 342, in parse
    compiled_result = compile_func(self, token)
  File "/usr/local/lib/python2.7/dist-packages/django/template/loader_tags.py", line 184, in do_block
    nodelist = parser.parse(('endblock',))
  File "/usr/local/lib/python2.7/dist-packages/django/template/base.py", line 342, in parse
    compiled_result = compile_func(self, token)
  File "/usr/local/lib/python2.7/dist-packages/django/template/defaulttags.py", line 872, in do_for
    nodelist_loop = parser.parse(('empty', 'endfor',))
  File "/usr/local/lib/python2.7/dist-packages/django/template/base.py", line 342, in parse
    compiled_result = compile_func(self, token)
  File "/usr/local/lib/python2.7/dist-packages/django/template/defaulttags.py", line 1014, in do_if
    nodelist = parser.parse(('elif', 'else', 'endif'))
  File "/usr/local/lib/python2.7/dist-packages/django/template/base.py", line 318, in parse
    filter_expression = self.compile_filter(token.contents)
  File "/usr/local/lib/python2.7/dist-packages/django/template/base.py", line 424, in compile_filter
    return FilterExpression(token, self)
  File "/usr/local/lib/python2.7/dist-packages/django/template/base.py", line 613, in __init__
    token[start:]))
TemplateSyntaxError: Could not parse some characters: estate_item.agency_price|/1000||default_if_none:''|intcomma
